Workbook

Sheet Übersicht
A1: Neue Mitte Werlte, Baufeld 3: Bankunterlagen
A2: Große Gastro im EG (ca. 510 m²), 2 Büro-Ankermieter und 3 Wohnungen im 1. OG, 5 Wohnungen im Staffelgeschoss in Holzbau. Bauherr: Bessam Hasso. Stand Oktober 2026.
A4: Kennzahl | B4: Wert | C4: Erläuterung
A5: Projekt
A6: Grundstück (m²) | B6: =Annahmen!$B$5 -> 960 | C6: Baufeld 3, Neue Mitte Werlte
A7: Grundfläche Gebäude (m²) | B7: =Annahmen!$B$10 -> 576 | C7: 32 × 18 m = GRZ-Maximum (0,6 × 960 m²)
A8: Bruttogrundfläche gesamt (m²) | B8: ='Flächen und Mieten'!B8 -> 1650 | C8: EG 576, 1. OG 576, Staffel 498
A9: Gastrofläche (m²) | B9: =Annahmen!$B$21 -> 510 | C9: ca. 190 Plätze innen, ca. 60 Terrasse
A10: Büro-Ankermieter (m²) | B10: ='Gewerbe und Anker'!B24 -> 165 | C10: 100 m² Versicherung o. ä. und 65 m² Makler o. ä., 10 Jahre fest
A11: Wohneinheiten | B11: ='Flächen und Mieten'!D9 -> 8 | C11: 3 im 1. OG (ca. 107 m²), 5 im Staffelgeschoss (ca. 67 m²)
A12: Wohnfläche gesamt (m²) | B12: ='Flächen und Mieten'!E9 -> 655
A13: Kosten und Finanzierung
A14: Gesamtkosten | B14: ='Kosten und Finanzierung'!B18 -> 4845505.7 | C14: inkl. Finanzierungskosten der Bau- und Anlaufzeit
A15: Darlehen gesamt (100 % Fremdkapital) | B15: ='Kosten und Finanzierung'!B29 -> 4845505.7 | C15: kein Eigenkapital
A16: davon KfW 297/298/299 | B16: =SUM('Kosten und Finanzierung'!B24:B26) -> 2347500 | C16: zinsverbilligt
A17: Anteil KfW | B17: ='Kosten und Finanzierung'!B30 -> 0.48446956
A18: Mischzins | B18: ='Kosten und Finanzierung'!B31 -> 0.033917044 | C18: KfW 2,5 % / 3,0 %, Hausbank 4,0 % (Annahmen)
A19: Kapitaldienst pro Monat (Anfangstilgung 1 %) | B19: =Tilgungsplan!N3 -> 17733.357 | C19: nach 12 Monaten tilgungsfreier Anlaufzeit
A20: Restschuld nach 10 Jahren Zinsbindung | B20: ='Tilgung Jahre'!E14 -> 4269180.3
A21: Ertrag und Wert
A22: Mieten Wohnen + Büro + Pacht pro Monat | B22: ='Flächen und Mieten'!F26 -> 14020.588 | C22: Rohertrag
A23: Nettoertrag Immobilie pro Monat (nach Rücklagen) | B23: ='Ertrag und Cashflow'!B9 -> 12618.529
A24: Betriebsergebnis Gastro nach Pacht pro Monat | B24: ='Ertrag und Cashflow'!B10 -> 14728.05 | C24: bei dem Umsatz aus Blatt Gastro Tagesteile, ohne Lohn des Bauherrn
A25: Ergebnis pro Monat nach Kapitaldienst | B25: ='Ertrag und Cashflow'!B13 -> 9613.2223
A26: Kapitaldienstdeckung gesamt (DSCR) | B26: ='Ertrag und Cashflow'!B15 -> 1.5420983 | C26: Bank verlangt meist mindestens 1,2
A27: Kapitaldienstdeckung nur Immobilie | B27: ='Ertrag und Cashflow'!B16 -> 0.71157025 | C27: ohne Gastro-Gewinn
A28: Kapitaldienstdeckung nur Wohnen und Büro | B28: ='Ertrag und Cashflow'!B17 -> 0.45273601 | C28: langfristige Mieten ohne Gastro
A29: Ertragswert | B29: =Ertragswert!E19 -> 2877244 | C29: Ertragswertverfahren nach Nutzung
A30: Beleihungswert nach Abschlag | B30: =Ertragswert!B26 -> 2589519.6
A31: Beleihungsauslauf | B31: =Ertragswert!B29 -> 1.8711987 | C31: Darlehen / Beleihungswert
A32: Airbnb für 1 Apartment (60 m²) | B32: ='Airbnb Prüfung'!A23 -> Kein Szenario erreicht den Mindest-Mehrertrag von 300 € pro Monat. Langfristige Vermietung ist besser, Airbnb bleibt aus dem Konzept.
A34: Alle Beträge sind Planungsannahmen. KfW-Zinsen und Rahmen sind Stand Ratgeber Oktober 2026 und müssen bei Hausbank und KfW bestätigt werden.

Sheet Annahmen
A1: Annahmen
A2: Blaue Zellen sind Eingaben, alle anderen Blätter rechnen daraus. Quelle 'Bauherr' = Vorgabe von Bessam Hasso, 'Annahme' = Planungsannahme ohne Beleg.
A3: Annahme | B3: Wert | C3: Quelle / Hinweis
A4: Grundstück
A5: Grundstücksfläche (m²) | B5: 960 | C5: Konzeptheft Neue Mitte Werlte, Baufeld 3
A6: Kaufpreis je m² (€) | B6: 230 | C6: Bauherr / Stadt Werlte
A7: Grunderwerbsteuer | B7: 0.05 | C7: Niedersachsen 5,0 %
A8: Notar und Grundbuch | B8: 0.02 | C8: Annahme
A9: Bauwerk
A10: BGF Erdgeschoss (m²) | B10: 576 | C10: Grundfläche 32 × 18 m = GRZ-Maximum 0,6 × 960 m² = 576 m²
A11: BGF 1. Obergeschoss (m²) | B11: 576 | C11: zweites Vollgeschoss: 2 Büros und 3 Wohnungen
A12: BGF Staffelgeschoss in Holzbau (m²) | B12: 498 | C12: 0,8 m rundum zurückgesetzt: 30,4 × 16,4 m, 5 Wohnungen
A13: Baukosten je m² BGF (€) | B13: 2200 | C13: Bauherr (Bekanntenpreis), durch Angebote zu belegen
A14: Holzbau günstiger als Massivbau (€/m²) | B14: 400 | C14: Annahme, Angebot der Zimmerei nötig
A15: Umlaufende Dachterrasse (m²) | B15: 77 | C15: schmal, ca. 0,8 m, zählt nicht zur BGF
A16: Dachterrasse Preis (€/m²) | B16: 450 | C16: Annahme
A17: Baunebenkosten | B17: 0.15 | C17: Architekt, Statik, Gebühren; Annahme
A18: Mehrkosten Effizienzhaus 40 und QNG | B18: 0.03 | C18: Annahme, auf Bau inkl. Baunebenkosten; Architekt muss bestätigen
A19: Gastro-Ausbau (€) | B19: 190000 | C19: Bauherr: 150.000 € für 150 Plätze, hier 1.000 € je Platz bei 190 Plätzen; Angebote nötig
A20: Flächen und Nutzung
A21: Gastrofläche im EG (m²) | B21: 510 | C21: EG abzüglich Treppenhaus, Aufzug, Eingänge (66 m²); Bedarf siehe Blatt Gewerbe und Anker
A22: Nettogrundfläche Anteil der Gastrofläche | B22: 0.85 | C22: Annahme, für KfW 299
A23: Wohnfläche 1. OG (m²) | B23: 321 | C23: 3 Wohnungen à ca. 107 m² (OG: 576 m² BGF minus Büros, Treppenhaus, Wände)
A24: Wohnungen im 1. OG | B24: 3 | C24: Bauherr: 8 Wohnungen insgesamt
A25: Wohnfläche Staffelgeschoss (m²) | B25: 334 | C25: 5 Wohnungen à ca. 67 m² (67 % der BGF)
A26: Wohnungen im Staffelgeschoss | B26: 5 | C26: Bauherr: 8 Wohnungen insgesamt
A27: davon vom Bauherrn selbst genutzt (Anzahl) | B27: 0 | C27: 0 = alle vermietet. Selbstnutzung: KfW 297 statt 298, Miete entfällt
A28: Ankermieter Büro (1. OG, mit Aufzug)
A29: Büro 1, Versicherungsgesellschaft o. ä. (m²) | B29: 100 | C29: Bauherr: größeres Büro, langfristiger Ankermieter
A30: Büro 1: Kaltmiete (€/m²) | B30: 9.5 | C30: Annahme: Neubau-Büro im Mittelzentrum ca. 8–11 €/m²; keine Marktdaten für Werlte gefunden
A31: Büro 2, kleiner Makler o. ä. (m²) | B31: 65 | C31: Bauherr: kleineres Büro
A32: Büro 2: Kaltmiete (€/m²) | B32: 10 | C32: Annahme, kleine Einheit etwas teurer je m²
A33: Mietvertragslaufzeit Ankermieter (Jahre) | B33: 10 | C33: Annahme: 10 Jahre fest, Indexmiete
A34: Vermieter-Ausbau der Büros (€/m²) | B34: 150 | C34: Annahme: Böden, Decken, Elektro-Grundausbau; Rest Mieter
A35: Gastro-Flächenbedarf (Richtwerte)
A36: Plätze im Gastraum inkl. Bar und Lounge | B36: 160 | C36: Planung
A37: Plätze im Séparée | B37: 30 | C37: Planung
A38: Fläche je Platz im Gastraum (m²) | B38: 1.9 | C38: Richtwert Gastraum 1,6–2,2 m² je Platz
A39: Fläche je Platz im Séparée (m²) | B39: 1.4 | C39: Richtwert Festtafel
A40: Bar- und Theken-Zone (m²) | B40: 45 | C40: große Theke, Backbar, Service, Stehtische (Bar im Fokus)
...

Sheet Flächen und Mieten
A1: Flächenprogramm und Mietaufstellung
A2: Grundfläche 32 × 18 m (GRZ-Maximum): Gastro im EG, 2 Ankermieter-Büros und 3 Wohnungen im 1. OG, 5 Wohnungen im Staffelgeschoss.
A4: Geschoss | B4: BGF (m²) | C4: Nutzung | D4: Einheiten | E4: Fläche (m²)
A5: Erdgeschoss | B5: =Annahmen!$B$10 -> 576 | C5: Gastro | D5: 1 | E5: =Annahmen!$B$21 -> 510
A6: 1. Obergeschoss | B6: =Annahmen!$B$11 -> 576 | C6: Büro + Wohnen | D6: =2+Annahmen!$B$24 -> 5 | E6: =Annahmen!$B$23+Annahmen!$B$29+Annahmen!$B$31 -> 486
A7: Staffelgeschoss (Holzbau) | B7: =Annahmen!$B$12 -> 498 | C7: Wohnen | D7: =Annahmen!$B$26 -> 5 | E7: =Annahmen!$B$25 -> 334
A8: Summe | B8: =SUM(B5:B7) -> 1650 | D8: =D5+D6+D7 -> 11 | E8: =SUM(E5:E7) -> 1330
A9: davon Wohneinheiten / Wohnfläche | D9: =Annahmen!$B$24+Annahmen!$B$26 -> 8 | E9: =Annahmen!$B$23+Annahmen!$B$25 -> 655
A11: Einheit | B11: Geschoss | C11: Fläche (m²) | D11: Nutzung | E11: Kaltmiete / m² | F11: Kaltmiete / Monat | G11: Kaltmiete / Jahr
A12: WE 1 | B12: 1. OG | C12: =Annahmen!$B$23/Annahmen!$B$24 -> 107 | D12: =IF(1>Annahmen!$B$24+Annahmen!$B$26-Annahmen!$B$27,"Eigennutzung","vermietet") -> vermietet | E12: =Annahmen!$B$46 -> 11.176471 | F12: =C12*E12 -> 1195.8824 | G12: =F12*12 -> 14350.588
A13: WE 2 | B13: 1. OG | C13: =Annahmen!$B$23/Annahmen!$B$24 -> 107 | D13: =IF(2>Annahmen!$B$24+Annahmen!$B$26-Annahmen!$B$27,"Eigennutzung","vermietet") -> vermietet | E13: =Annahmen!$B$46 -> 11.176471 | F13: =C13*E13 -> 1195.8824 | G13: =F13*12 -> 14350.588
A14: WE 3 | B14: 1. OG | C14: =Annahmen!$B$23/Annahmen!$B$24 -> 107 | D14: =IF(3>Annahmen!$B$24+Annahmen!$B$26-Annahmen!$B$27,"Eigennutzung","vermietet") -> vermietet | E14: =Annahmen!$B$46 -> 11.176471 | F14: =C14*E14 -> 1195.8824 | G14: =F14*12 -> 14350.588
A15: WE 4 | B15: Staffel | C15: =Annahmen!$B$25/Annahmen!$B$26 -> 66.8 | D15: =IF(4>Annahmen!$B$24+Annahmen!$B$26-Annahmen!$B$27,"Eigennutzung","vermietet") -> vermietet | E15: =Annahmen!$B$46 -> 11.176471 | F15: =C15*E15 -> 746.58824 | G15: =F15*12 -> 8959.0588
A16: WE 5 | B16: Staffel | C16: =Annahmen!$B$25/Annahmen!$B$26 -> 66.8 | D16: =IF(5>Annahmen!$B$24+Annahmen!$B$26-Annahmen!$B$27,"Eigennutzung","vermietet") -> vermietet | E16: =Annahmen!$B$46 -> 11.176471 | F16: =C16*E16 -> 746.58824 | G16: =F16*12 -> 8959.0588
A17: WE 6 | B17: Staffel | C17: =Annahmen!$B$25/Annahmen!$B$26 -> 66.8 | D17: =IF(6>Annahmen!$B$24+Annahmen!$B$26-Annahmen!$B$27,"Eigennutzung","vermietet") -> vermietet | E17: =Annahmen!$B$46 -> 11.176471 | F17: =C17*E17 -> 746.58824 | G17: =F17*12 -> 8959.0588
A18: WE 7 | B18: Staffel | C18: =Annahmen!$B$25/Annahmen!$B$26 -> 66.8 | D18: =IF(7>Annahmen!$B$24+Annahmen!$B$26-Annahmen!$B$27,"Eigennutzung","vermietet") -> vermietet | E18: =Annahmen!$B$46 -> 11.176471 | F18: =C18*E18 -> 746.58824 | G18: =F18*12 -> 8959.0588
A19: WE 8 | B19: Staffel | C19: =Annahmen!$B$25/Annahmen!$B$26 -> 66.8 | D19: =IF(8>Annahmen!$B$24+Annahmen!$B$26-Annahmen!$B$27,"Eigennutzung","vermietet") -> vermietet | E19: =Annahmen!$B$46 -> 11.176471 | F19: =C19*E19 -> 746.58824 | G19: =F19*12 -> 8959.0588
A20: Summe Wohnen (alle Wohnungen, marktüblich) | C20: =SUM(C12:C19) -> 655 | F20: =SUM(F12:F19) -> 7320.5882 | G20: =SUM(G12:G19) -> 87847.059
A21: davon vermietet (Einnahmen) | F21: =SUMIF(D12:D19,"vermietet",F12:F19) -> 7320.5882 | G21: =F21*12 -> 87847.059
A22: Gastro-Pacht (Gastro zahlt an das Haus) | C22: =Annahmen!$B$21 -> 510 | E22: =Annahmen!$B$47 -> 10 | F22: =C22*E22 -> 5100 | G22: =F22*12 -> 61200
A23: Büro 1 (Ankermieter, Versicherung o. ä.) | B23: 1. OG | C23: =Annahmen!$B$29 -> 100 | D23: =Annahmen!$B$33&" Jahre fest" -> 10 Jahre fest | E23: =Annahmen!$B$30 -> 9.5 | F23: =C23*E23 -> 950 | G23: =F23*12 -> 11400
A24: Büro 2 (Makler o. ä.) | B24: 1. OG | C24: =Annahmen!$B$31 -> 65 | D24: =Annahmen!$B$33&" Jahre fest" -> 10 Jahre fest | E24: =Annahmen!$B$32 -> 10 | F24: =C24*E24 -> 650 | G24: =F24*12 -> 7800
A25: Büromieten gesamt | C25: =C23+C24 -> 165 | F25: =F23+F24 -> 1600 | G25: =G23+G24 -> 19200
A26: Rohertrag gesamt (Wohnen vermietet + Büro + Pacht) | F26: =F21+F22+F25 -> 14020.588 | G26: =G21+G22+G25 -> 168247.06
A28: Nebenkosten (Grundsteuer, Versicherung, Betriebskosten) werden auf die Mieter umgelegt und sind hier nicht gerechnet. Mieten sind Annahmen des Bauherrn bzw. Planungsannahmen.

Sheet Gewerbe und Anker
A1: Gewerbeflächen: Gastro-Flächenbedarf und Ankermieter Büro
A2: Gastro im ganzen EG nach Bedarf (aus Plätzen), zwei Büros im 1. OG als langfristige Ankermieter (Aufzug, getrennter Eingang).
A4: Gastro-Flächenbedarf | B4: Menge | C4: m² je Einheit | D4: Fläche (m²) | H4: Hinweis
A5: Gastraum inkl. Lounge | B5: =Annahmen!$B$36 -> 160 | C5: =Annahmen!$B$38 -> 1.9 | D5: =B5*C5 -> 304 | H5: Plätze × Richtwert
A6: Séparée (Feiern) | B6: =Annahmen!$B$37 -> 30 | C6: =Annahmen!$B$39 -> 1.4 | D6: =B6*C6 -> 42 | H6: Festtafel
A7: Bar und Theken-Zone | B7: 1 | C7: =Annahmen!$B$40 -> 45 | D7: =B7*C7 -> 45
A8: Küche (Bowls, Snacks) mit Spülküche | B8: 1 | C8: =Annahmen!$B$41 -> 35 | D8: =B8*C8 -> 35
A9: Lager, Kühlung, Anlieferung | B9: 1 | C9: =Annahmen!$B$42 -> 25 | D9: =B9*C9 -> 25
A10: WC (Herren, Damen, barrierefrei) | B10: 1 | C10: =Annahmen!$B$43 -> 22 | D10: =B10*C10 -> 22
A11: Eingang, Garderobe, Flure, Technik | B11: 1 | C11: =Annahmen!$B$44 -> 37 | D11: =B11*C11 -> 37
A12: Gastrofläche aus Bedarf | D12: =SUM(D5:D11) -> 510
A13: Gastrofläche im Modell (Annahmen) | D13: =Annahmen!$B$21 -> 510
A14: Abweichung (Bedarf minus Modell) | D14: =D12-D13 -> 0
A15: Plätze innen gesamt | D15: =B5+B6 -> 190
A16: Bruttofläche je Platz (m²) | D16: =D13/D15 -> 2.6842105 | H16: Richtwert Gesamtfläche 2,5–3 m² je Platz
A17: Gastro-Umsatz je Platz und Jahr (€) | D17: =Annahmen!$B$49*12/D15 -> 4105.8947 | H17: Österreich Median ca. 12.000 €
A18: Pacht in % vom Gastro-Umsatz | D18: ='Flächen und Mieten'!F22/Annahmen!$B$49 -> 0.078449469 | H18: üblich 6–12 %
A21: Ankermieter Büro | B21: Fläche (m²) | C21: Miete €/m² | D21: Miete / Monat | E21: Miete / Jahr | F21: Laufzeit (Jahre) | G21: Miete über Laufzeit | H21: Anteil am Rohertrag
A22: Büro 1: Versicherungsgesellschaft o. ä. | B22: =Annahmen!$B$29 -> 100 | C22: =Annahmen!$B$30 -> 9.5 | D22: =B22*C22 -> 950 | E22: =D22*12 -> 11400 | F22: =Annahmen!$B$33 -> 10 | G22: =E22*((1+Annahmen!$B$80)^F22-1)/Annahmen!$B$80 -> 124826.82 | H22: =E22/'Flächen und Mieten'!$G$26 -> 0.067757499
A23: Büro 2: Makler o. ä. | B23: =Annahmen!$B$31 -> 65 | C23: =Annahmen!$B$32 -> 10 | D23: =B23*C23 -> 650 | E23: =D23*12 -> 7800 | F23: =Annahmen!$B$33 -> 10 | G23: =E23*((1+Annahmen!$B$80)^F23-1)/Annahmen!$B$80 -> 85407.824 | H23: =E23/'Flächen und Mieten'!$G$26 -> 0.046360394
A24: Summe Büro | B24: =SUM(B22:B23) -> 165 | C24: =D24/B24 -> 9.6969697 | D24: =SUM(D22:D23) -> 1600 | E24: =SUM(E22:E23) -> 19200 | G24: =SUM(G22:G23) -> 210234.64 | H24: =SUM(H22:H23) -> 0.11411789
A26: Deckung des Kapitaldienstes durch langfristige Mieten
A27: Kapitaldienst pro Jahr | D27: =Tilgungsplan!N3*12 -> 212800.29
A28: Büromieten nach Rücklagen pro Jahr | D28: =E24*(1-Annahmen!$B$48) -> 17280
A29: davon gedeckter Anteil des Kapitaldienstes | D29: =D28/D27 -> 0.081202899
A30: Wohnen und Büro nach Rücklagen pro Jahr | D30: =('Flächen und Mieten'!G21+E24)*(1-Annahmen!$B$48) -> 96342.353
A31: davon gedeckter Anteil des Kapitaldienstes (ohne Gastro) | D31: =D30/D27 -> 0.45273601
A32: Mietdauer-gewichtete Restlaufzeit der Büro-Verträge (Jahre) | D32: =SUMPRODUCT(E22:E23,F22:F23)/E24 -> 10
A34: Stellplatzbedarf (grobe Annahme)
A35: Wohnungen: 1,5 je Wohnung | D35: =(Annahmen!$B$24+Annahmen!$B$26)*1.5 -> 12
A36: Gastro: 1 je 10 m² Gastraum (Gastraum, Séparée, Bar) | D36: =(D5+D6+D7)/10 -> 39.1
A37: Büro: 1 je 30 m² | D37: =B24/30 -> 5.5
A38: Stellplatzbedarf gesamt | D38: =SUM(D35:D37) -> 56.6 | H38: Stellplatzsatzung der Stadt gilt verbindlich
A40: Hinweis: Büromieten und Laufzeiten sind Annahmen, für Werlte liegen keine Büromarktdaten vor. Anker-Mietverträge (Vorverträge) vor Baubeginn sichern.

Sheet Kosten und Finanzierung
A1: Kosten und Finanzierungsplan
A2: Mittelverwendung und Mittelherkunft. 100 % Fremdfinanzierung, kein Eigenkapital.
A4: Mittelverwendung (Kosten) | B4: Betrag | C4: Anteil | D4: Rechnung
A5: Grundstück (Kaufpreis) | B5: =Annahmen!$B$5*Annahmen!$B$6 -> 220800 | C5: =B5/$B$18 -> 0.045567999 | D5: m² × Preis
A6: Grunderwerbsteuer | B6: =B5*Annahmen!$B$7 -> 11040 | C6: =B6/$B$18 -> 0.0022784
A7: Notar und Grundbuch | B7: =B5*Annahmen!$B$8 -> 4416 | C7: =B7/$B$18 -> 0.00091135998
A8: Grundstück gesamt | B8: =SUM(B5:B7) -> 236256 | C8: =B8/$B$18 -> 0.048757759
A9: Bau, Massivbau (BGF × Baukosten) | B9: =(Annahmen!$B$10+Annahmen!$B$11+Annahmen!$B$12)*Annahmen!$B$13 -> 3630000 | C9: =B9/$B$18 -> 0.74914781 | D9: =TEXT(Annahmen!$B$10+Annahmen!$B$11+Annahmen!$B$12,"#,##0")&" m² × "&TEXT(Annahmen!$B$13,"#,##0")&" €" -> 1,650 m² × 2,200 €
A10: Abschlag Holzbau Staffelgeschoss | B10: =-Annahmen!$B$12*Annahmen!$B$14 -> -199200 | C10: =B10/$B$18 -> -0.04111026 | D10: =TEXT(Annahmen!$B$12,"#,##0")&" m² × "&TEXT(Annahmen!$B$14,"#,##0")&" €" -> 498 m² × 400 €
A11: Dachterrasse rundum | B11: =Annahmen!$B$15*Annahmen!$B$16 -> 34650 | C11: =B11/$B$18 -> 0.0071509564 | D11: =TEXT(Annahmen!$B$15,"#,##0")&" m² × "&TEXT(Annahmen!$B$16,"#,##0")&" €" -> 77 m² × 450 €
A12: Bau gesamt | B12: =SUM(B9:B11) -> 3465450 | C12: =B12/$B$18 -> 0.71518851
A13: Baunebenkosten | B13: =B12*Annahmen!$B$17 -> 519817.5 | C13: =B13/$B$18 -> 0.10727828 | D13: 15 % vom Bau
A14: Mehrkosten Effizienzhaus 40 und QNG-Nachweis | B14: =(B12+B13)*Annahmen!$B$18 -> 119558.02 | C14: =B14/$B$18 -> 0.024674004 | D14: 3 % auf Bau inkl. Baunebenkosten
A15: Ausbau Gastro (Küche, Bar, Möbel, Technik) und Büros (Vermieter-Ausbau) | B15: =Annahmen!$B$19+(Annahmen!$B$29+Annahmen!$B$31)*Annahmen!$B$34 -> 214750 | C15: =B15/$B$18 -> 0.044319419 | D15: Gastro 1.000 € je Platz, Büros 150 €/m²
A16: Investitionskosten ohne Finanzierung | B16: =B8+B12+B13+B14+B15 -> 4555831.5 | C16: =B16/$B$18 -> 0.94021797
A17: Finanzierungskosten (Bauzeit, Bereitstellung, Anlaufzeit) | B17: =Bauphase!G36 -> 289674.18 | C17: =B17/$B$18 -> 0.059782033 | D17: aus Blatt Bauphase
A18: Gesamtkosten des Vorhabens | B18: =B16+B17 -> 4845505.7 | C18: =B18/$B$18 -> 1
A19: Kosten je m² BGF | B19: =B18/'Flächen und Mieten'!B8 -> 2936.6701
A20: Kosten je Wohneinheit (Gesamtkosten / 8, inkl. Gewerbe) | B20: =B18/'Flächen und Mieten'!D9 -> 605688.21
A23: Mittelherkunft (Finanzierung) | B23: Betrag bei Rate-Start | C23: Anteil | D23: Zins / Programm
A24: KfW 297 Klimafreundlicher Neubau (selbst genutzte Wohnungen) | B24: =Bauphase!L33*Annahmen!$B$27/MAX(1,(Annahmen!$B$24+Annahmen!$B$26)) -> 0 | C24: =B24/$B$29 -> 0 | D24: =Annahmen!$B$55 -> 0.025
A25: KfW 298 Klimafreundlicher Neubau (vermietete Wohnungen) | B25: =Bauphase!L33-B24 -> 1200000 | C25: =B25/$B$29 -> 0.24765217 | D25: =Annahmen!$B$55 -> 0.025
A26: KfW 299 Klimafreundlicher Neubau (Nichtwohngebäude: Gastro und Büros) | B26: =Bauphase!M33 -> 1147500 | C26: =B26/$B$29 -> 0.23681739 | D26: =Annahmen!$B$56 -> 0.03
A27: Hausbank-Darlehen (Restfinanzierung inkl. Zinsen der Bauzeit) | B27: =Bauphase!N33 -> 2498005.7 | C27: =B27/$B$29 -> 0.51553044 | D27: =Annahmen!$B$57 -> 0.04
A28: Eigenkapital | B28: 0 | C28: =B28/$B$29 -> 0
A29: Summe Finanzierung | B29: =SUM(B24:B28) -> 4845505.7 | C29: =B29/$B$29 -> 1
A30: Anteil KfW-Kredite an der Finanzierung | B30: =(B24+B25+B26)/B29 -> 0.48446956
A31: Mischzins aller Darlehen | B31: =(B24*Annahmen!$B$55+B25*Annahmen!$B$55+B26*Annahmen!$B$56+B27*Annahmen!$B$57)/B29 -> 0.033917044
A33: KfW-Rahmen laut Programm (Stand Ratgeber Okt. 2026, bei Hausbank und KfW zu bestätigen):
A34: KfW 297/298: Rahmen Wohnen (Wohneinheiten × 150.000 €) | B34: =(Annahmen!$B$24+Annahmen!$B$26)*Annahmen!$B$53 -> 1200000
A35: KfW 299: Rahmen Gastro und Büros (Nettogrundfläche × 2.000 €) | B35: =(Annahmen!$B$21+Annahmen!$B$29+Annahmen!$B$31)*Annahmen!$B$22*Annahmen!$B$54 -> 1147500
A36: KfW-Rahmen gesamt | B36: =B34+B35 -> 2347500
A37: Antrag nur mit Effizienzhaus 40, QNG-Zertifikat, Heizung ohne Öl, Gas und Biomasse, vor Baubeginn über die Hausbank.

Sheet Bauphase
A1: Bauphase und Anlaufzeit: Abrufe, Zinsen, Kreditstand
A2: Monat 0 = Grundstück. Monate 1–15 Bau. Monate 16–27 tilgungsfreie Anlaufzeit. KfW-Darlehen werden anteilig zu den Ausgaben abgerufen, die Hausbank zahlt zusätzlich alle Zinsen.
A3: Anteil KfW Wohnen an den Ausgaben | E3: =MIN(1,'Kosten und Finanzierung'!B34/'Kosten und Finanzierung'!B16) -> 0.26339868 | F3: Anteil KfW Gastro | I3: =MIN(1-E3,'Kosten und Finanzierung'!B35/'Kosten und Finanzierung'!B16) -> 0.25187499 | J3: Anteil Hausbank | L3: =1-E3-I3 -> 0.48472634
A5: Monat | B5: Phase | C5: Ausgaben (Grundstück, Bau) | D5: Offene Bausumme | E5: Abruf KfW Wohnen | F5: Abruf KfW Gastro | G5: Zinsen KfW Wohnen | H5: Zinsen KfW Gastro | I5: Zinsen Hausbank | J5: Bereitstellungs-zins | K5: Abruf Hausbank | L5: Stand KfW Wohnen | M5: Stand KfW Gastro | N5: Stand Hausbank
A6: 0 | B6: Grundstück | C6: ='Kosten und Finanzierung'!B8 -> 236256 | D6: =('Kosten und Finanzierung'!B16-'Kosten und Finanzierung'!B8) -> 4319575.5 | E6: =C6*$E$3 -> 62229.518 | F6: =C6*$I$3 -> 59506.977 | G6: 0 | H6: 0 | I6: 0 | J6: 0 | K6: =C6*$L$3+G6+H6+I6+J6 -> 114519.51 | L6: =E6 -> 62229.518 | M6: =F6 -> 59506.977 | N6: =K6 -> 114519.51
A7: 1 | B7: Bau | C7: =IF(A7<=Annahmen!$B$59,('Kosten und Finanzierung'!B16-'Kosten und Finanzierung'!B8)/Annahmen!$B$59,0) -> 287971.7 | D7: =IF(A7<=Annahmen!$B$59,('Kosten und Finanzierung'!B16-'Kosten und Finanzierung'!B8)*(Annahmen!$B$59-(A7-1))/Annahmen!$B$59,0) -> 4319575.5 | E7: =C7*$E$3 -> 75851.365 | F7: =C7*$I$3 -> 72532.868 | G7: =L6*Annahmen!$B$55/12 -> 129.64483 | H7: =M6*Annahmen!$B$56/12 -> 148.76744 | I7: =N6*Annahmen!$B$57/12 -> 381.73168 | J7: =IF(AND(A7>=Annahmen!$B$62,A7<=Annahmen!$B$59),D7*Annahmen!$B$61/12,0) -> 0 | K7: =C7*$L$3+G7+H7+I7+J7 -> 140247.61 | L7: =L6+E7 -> 138080.88 | M7: =M6+F7 -> 132039.84 | N7: =N6+K7 -> 254767.12
A8: 2 | B8: Bau | C8: =IF(A8<=Annahmen!$B$59,('Kosten und Finanzierung'!B16-'Kosten und Finanzierung'!B8)/Annahmen!$B$59,0) -> 287971.7 | D8: =IF(A8<=Annahmen!$B$59,('Kosten und Finanzierung'!B16-'Kosten und Finanzierung'!B8)*(Annahmen!$B$59-(A8-1))/Annahmen!$B$59,0) -> 4031603.8 | E8: =C8*$E$3 -> 75851.365 | F8: =C8*$I$3 -> 72532.868 | G8: =L7*Annahmen!$B$55/12 -> 287.66851 | H8: =M7*Annahmen!$B$56/12 -> 330.09961 | I8: =N7*Annahmen!$B$57/12 -> 849.22372 | J8: =IF(AND(A8>=Annahmen!$B$62,A8<=Annahmen!$B$59),D8*Annahmen!$B$61/12,0) -> 0 | K8: =C8*$L$3+G8+H8+I8+J8 -> 141054.46 | L8: =L7+E8 -> 213932.25 | M8: =M7+F8 -> 204572.71 | N8: =N7+K8 -> 395821.58
A9: 3 | B9: Bau | C9: =IF(A9<=Annahmen!$B$59,('Kosten und Finanzierung'!B16-'Kosten und Finanzierung'!B8)/Annahmen!$B$59,0) -> 287971.7 | D9: =IF(A9<=Annahmen!$B$59,('Kosten und Finanzierung'!B16-'Kosten und Finanzierung'!B8)*(Annahmen!$B$59-(A9-1))/Annahmen!$B$59,0) -> 3743632.1 | E9: =C9*$E$3 -> 75851.365 | F9: =C9*$I$3 -> 72532.868 | G9: =L8*Annahmen!$B$55/12 -> 445.69219 | H9: =M8*Annahmen!$B$56/12 -> 511.43178 | I9: =N8*Annahmen!$B$57/12 -> 1319.4053 | J9: =IF(AND(A9>=Annahmen!$B$62,A9<=Annahmen!$B$59),D9*Annahmen!$B$61/12,0) -> 0 | K9: =C9*$L$3+G9+H9+I9+J9 -> 141864 | L9: =L8+E9 -> 289783.61 | M9: =M8+F9 -> 277105.58 | N9: =N8+K9 -> 537685.57
A10: 4 | B10: Bau | C10: =IF(A10<=Annahmen!$B$59,('Kosten und Finanzierung'!B16-'Kosten und Finanzierung'!B8)/Annahmen!$B$59,0) -> 287971.7 | D10: =IF(A10<=Annahmen!$B$59,('Kosten und Finanzierung'!B16-'Kosten und Finanzierung'!B8)*(Annahmen!$B$59-(A10-1))/Annahmen!$B$59,0) -> 3455660.4 | E10: =C10*$E$3 -> 75851.365 | F10: =C10*$I$3 -> 72532.868 | G10: =L9*Annahmen!$B$55/12 -> 603.71586 | H10: =M9*Annahmen!$B$56/12 -> 692.76395 | I10: =N9*Annahmen!$B$57/12 -> 1792.2852 | J10: =IF(AND(A10>=Annahmen!$B$62,A10<=Annahmen!$B$59),D10*Annahmen!$B$61/12,0) -> 0 | K10: =C10*$L$3+G10+H10+I10+J10 -> 142676.23 | L10: =L9+E10 -> 365634.98 | M10: =M9+F10 -> 349638.45 | N10: =N9+K10 -> 680361.81
A11: 5 | B11: Bau | C11: =IF(A11<=Annahmen!$B$59,('Kosten und Finanzierung'!B16-'Kosten und Finanzierung'!B8)/Annahmen!$B$59,0) -> 287971.7 | D11: =IF(A11<=Annahmen!$B$59,('Kosten und Finanzierung'!B16-'Kosten und Finanzierung'!B8)*(Annahmen!$B$59-(A11-1))/Annahmen!$B$59,0) -> 3167688.7 | E11: =C11*$E$3 -> 75851.365 | F11: =C11*$I$3 -> 72532.868 | G11: =L10*Annahmen!$B$55/12 -> 761.73954 | H11: =M10*Annahmen!$B$56/12 -> 874.09612 | I11: =N10*Annahmen!$B$57/12 -> 2267.8727 | J11: =IF(AND(A11>=Annahmen!$B$62,A11<=Annahmen!$B$59),D11*Annahmen!$B$61/12,0) -> 0 | K11: =C11*$L$3+G11+H11+I11+J11 -> 143491.18 | L11: =L10+E11 -> 441486.35 | M11: =M10+F11 -> 422171.32 | N11: =N10+K11 -> 823852.98
A12: 6 | B12: Bau | C12: =IF(A12<=Annahmen!$B$59,('Kosten und Finanzierung'!B16-'Kosten und Finanzierung'!B8)/Annahmen!$B$59,0) -> 287971.7 | D12: =IF(A12<=Annahmen!$B$59,('Kosten und Finanzierung'!B16-'Kosten und Finanzierung'!B8)*(Annahmen!$B$59-(A12-1))/Annahmen!$B$59,0) -> 2879717 | E12: =C12*$E$3 -> 75851.365 | F12: =C12*$I$3 -> 72532.868 | G12: =L11*Annahmen!$B$55/12 -> 919.76322 | H12: =M11*Annahmen!$B$56/12 -> 1055.4283 | I12: =N11*Annahmen!$B$57/12 -> 2746.1766 | J12: =IF(AND(A12>=Annahmen!$B$62,A12<=Annahmen!$B$59),D12*Annahmen!$B$61/12,0) -> 0 | K12: =C12*$L$3+G12+H12+I12+J12 -> 144308.84 | L12: =L11+E12 -> 517337.71 | M12: =M11+F12 -> 494704.19 | N12: =N11+K12 -> 968161.82
A13: 7 | B13: Bau | C13: =IF(A13<=Annahmen!$B$59,('Kosten und Finanzierung'!B16-'Kosten und Finanzierung'!B8)/Annahmen!$B$59,0) -> 287971.7 | D13: =IF(A13<=Annahmen!$B$59,('Kosten und Finanzierung'!B16-'Kosten und Finanzierung'!B8)*(Annahmen!$B$59-(A13-1))/Annahmen!$B$59,0) -> 2591745.3 | E13: =C13*$E$3 -> 75851.365 | F13: =C13*$I$3 -> 72532.868 | G13: =L12*Annahmen!$B$55/12 -> 1077.7869 | H13: =M12*Annahmen!$B$56/12 -> 1236.7605 | I13: =N12*Annahmen!$B$57/12 -> 3227.2061 | J13: =IF(AND(A13>=Annahmen!$B$62,A13<=Annahmen!$B$59),D13*Annahmen!$B$61/12,0) -> 6479.3633 | K13: =C13*$L$3+G13+H13+I13+J13 -> 151608.58 | L13: =L12+E13 -> 593189.08 | M13: =M12+F13 -> 567237.05 | N13: =N12+K13 -> 1119770.4
A14: 8 | B14: Bau | C14: =IF(A14<=Annahmen!$B$59,('Kosten und Finanzierung'!B16-'Kosten und Finanzierung'!B8)/Annahmen!$B$59,0) -> 287971.7 | D14: =IF(A14<=Annahmen!$B$59,('Kosten und Finanzierung'!B16-'Kosten und Finanzierung'!B8)*(Annahmen!$B$59-(A14-1))/Annahmen!$B$59,0) -> 2303773.6 | E14: =C14*$E$3 -> 75851.365 | F14: =C14*$I$3 -> 72532.868 | G14: =L13*Annahmen!$B$55/12 -> 1235.8106 | H14: =M13*Annahmen!$B$56/12 -> 1418.0926 | I14: =N13*Annahmen!$B$57/12 -> 3732.568 | J14: =IF(AND(A14>=Annahmen!$B$62,A14<=Annahmen!$B$59),D14*Annahmen!$B$61/12,0) -> 5759.434 | K14: =C14*$L$3+G14+H14+I14+J14 -> 151733.37 | L14: =L13+E14 -> 669040.44 | M14: =M13+F14 -> 639769.92 | N14: =N13+K14 -> 1271503.8
A15: 9 | B15: Bau | C15: =IF(A15<=Annahmen!$B$59,('Kosten und Finanzierung'!B16-'Kosten und Finanzierung'!B8)/Annahmen!$B$59,0) -> 287971.7 | D15: =IF(A15<=Annahmen!$B$59,('Kosten und Finanzierung'!B16-'Kosten und Finanzierung'!B8)*(Annahmen!$B$59-(A15-1))/Annahmen!$B$59,0) -> 2015801.9 | E15: =C15*$E$3 -> 75851.365 | F15: =C15*$I$3 -> 72532.868 | G15: =L14*Annahmen!$B$55/12 -> 1393.8343 | H15: =M14*Annahmen!$B$56/12 -> 1599.4248 | I15: =N14*Annahmen!$B$57/12 -> 4238.3459 | J15: =IF(AND(A15>=Annahmen!$B$62,A15<=Annahmen!$B$59),D15*Annahmen!$B$61/12,0) -> 5039.5048 | K15: =C15*$L$3+G15+H15+I15+J15 -> 151858.58 | L15: =L14+E15 -> 744891.81 | M15: =M14+F15 -> 712302.79 | N15: =N14+K15 -> 1423362.4
A16: 10 | B16: Bau | C16: =IF(A16<=Annahmen!$B$59,('Kosten und Finanzierung'!B16-'Kosten und Finanzierung'!B8)/Annahmen!$B$59,0) -> 287971.7 | D16: =IF(A16<=Annahmen!$B$59,('Kosten und Finanzierung'!B16-'Kosten und Finanzierung'!B8)*(Annahmen!$B$59-(A16-1))/Annahmen!$B$59,0) -> 1727830.2 | E16: =C16*$E$3 -> 75851.365 | F16: =C16*$I$3 -> 72532.868 | G16: =L15*Annahmen!$B$55/12 -> 1551.8579 | H16: =M15*Annahmen!$B$56/12 -> 1780.757 | I16: =N15*Annahmen!$B$57/12 -> 4744.5412 | J16: =IF(AND(A16>=Annahmen!$B$62,A16<=Annahmen!$B$59),D16*Annahmen!$B$61/12,0) -> 4319.5755 | K16: =C16*$L$3+G16+H16+I16+J16 -> 151984.2 | L16: =L15+E16 -> 820743.17 | M16: =M15+F16 -> 784835.66 | N16: =N15+K16 -> 1575346.6
A17: 11 | B17: Bau | C17: =IF(A17<=Annahmen!$B$59,('Kosten und Finanzierung'!B16-'Kosten und Finanzierung'!B8)/Annahmen!$B$59,0) -> 287971.7 | D17: =IF(A17<=Annahmen!$B$59,('Kosten und Finanzierung'!B16-'Kosten und Finanzierung'!B8)*(Annahmen!$B$59-(A17-1))/Annahmen!$B$59,0) -> 1439858.5 | E17: =C17*$E$3 -> 75851.365 | F17: =C17*$I$3 -> 72532.868 | G17: =L16*Annahmen!$B$55/12 -> 1709.8816 | H17: =M16*Annahmen!$B$56/12 -> 1962.0891 | I17: =N16*Annahmen!$B$57/12 -> 5251.1552 | J17: =IF(AND(A17>=Annahmen!$B$62,A17<=Annahmen!$B$59),D17*Annahmen!$B$61/12,0) -> 3599.6463 | K17: =C17*$L$3+G17+H17+I17+J17 -> 152110.24 | L17: =L16+E17 -> 896594.54 | M17: =M16+F17 -> 857368.53 | N17: =N16+K17 -> 1727456.8
A18: 12 | B18: Bau | C18: =IF(A18<=Annahmen!$B$59,('Kosten und Finanzierung'!B16-'Kosten und Finanzierung'!B8)/Annahmen!$B$59,0) -> 287971.7 | D18: =IF(A18<=Annahmen!$B$59,('Kosten und Finanzierung'!B16-'Kosten und Finanzierung'!B8)*(Annahmen!$B$59-(A18-1))/Annahmen!$B$59,0) -> 1151886.8 | E18: =C18*$E$3 -> 75851.365 | F18: =C18*$I$3 -> 72532.868 | G18: =L17*Annahmen!$B$55/12 -> 1867.9053 | H18: =M17*Annahmen!$B$56/12 -> 2143.4213 | I18: =N17*Annahmen!$B$57/12 -> 5758.1893 | J18: =IF(AND(A18>=Annahmen!$B$62,A18<=Annahmen!$B$59),D18*Annahmen!$B$61/12,0) -> 2879.717 | K18: =C18*$L$3+G18+H18+I18+J18 -> 152236.7 | L18: =L17+E18 -> 972445.9 | M18: =M17+F18 -> 929901.4 | N18: =N17+K18 -> 1879693.5
A19: 13 | B19: Bau | C19: =IF(A19<=Annahmen!$B$59,('Kosten und Finanzierung'!B16-'Kosten und Finanzierung'!B8)/Annahmen!$B$59,0) -> 287971.7 | D19: =IF(A19<=Annahmen!$B$59,('Kosten und Finanzierung'!B16-'Kosten und Finanzierung'!B8)*(Annahmen!$B$59-(A19-1))/Annahmen!$B$59,0) -> 863915.1 | E19: =C19*$E$3 -> 75851.365 | F19: =C19*$I$3 -> 72532.868 | G19: =L18*Annahmen!$B$55/12 -> 2025.929 | H19: =M18*Annahmen!$B$56/12 -> 2324.7535 | I19: =N18*Annahmen!$B$57/12 -> 6265.645 | J19: =IF(AND(A19>=Annahmen!$B$62,A19<=Annahmen!$B$59),D19*Annahmen!$B$61/12,0) -> 2159.7878 | K19: =C19*$L$3+G19+H19+I19+J19 -> 152363.58 | L19: =L18+E19 -> 1048297.3 | M19: =M18+F19 -> 1002434.3 | N19: =N18+K19 -> 2032057.1
A20: 14 | B20: Bau | C20: =IF(A20<=Annahmen!$B$59,('Kosten und Finanzierung'!B16-'Kosten und Finanzierung'!B8)/Annahmen!$B$59,0) -> 287971.7 | D20: =IF(A20<=Annahmen!$B$59,('Kosten und Finanzierung'!B16-'Kosten und Finanzierung'!B8)*(Annahmen!$B$59-(A20-1))/Annahmen!$B$59,0) -> 575943.4 | E20: =C20*$E$3 -> 75851.365 | F20: =C20*$I$3 -> 72532.868 | G20: =L19*Annahmen!$B$55/12 -> 2183.9526 | H20: =M19*Annahmen!$B$56/12 -> 2506.0857 | I20: =N19*Annahmen!$B$57/12 -> 6773.5236 | J20: =IF(AND(A20>=Annahmen!$B$62,A20<=Annahmen!$B$59),D20*Annahmen!$B$61/12,0) -> 1439.8585 | K20: =C20*$L$3+G20+H20+I20+J20 -> 152490.89 | L20: =L19+E20 -> 1124148.6 | M20: =M19+F20 -> 1074967.1 | N20: =N19+K20 -> 2184548
A21: 15 | B21: Bau | C21: =IF(A21<=Annahmen!$B$59,('Kosten und Finanzierung'!B16-'Kosten und Finanzierung'!B8)/Annahmen!$B$59,0) -> 287971.7 | D21: =IF(A21<=Annahmen!$B$59,('Kosten und Finanzierung'!B16-'Kosten und Finanzierung'!B8)*(Annahmen!$B$59-(A21-1))/Annahmen!$B$59,0) -> 287971.7 | E21: =C21*$E$3 -> 75851.365 | F21: =C21*$I$3 -> 72532.868 | G21: =L20*Annahmen!$B$55/12 -> 2341.9763 | H21: =M20*Annahmen!$B$56/12 -> 2687.4178 | I21: =N20*Annahmen!$B$57/12 -> 7281.8266 | J21: =IF(AND(A21>=Annahmen!$B$62,A21<=Annahmen!$B$59),D21*Annahmen!$B$61/12,0) -> 719.92925 | K21: =C21*$L$3+G21+H21+I21+J21 -> 152618.62 | L21: =L20+E21 -> 1200000 | M21: =M20+F21 -> 1147500 | N21: =N20+K21 -> 2337166.6
A22: 16 | B22: Anlaufzeit | C22: =IF(A22<=Annahmen!$B$59,('Kosten und Finanzierung'!B16-'Kosten und Finanzierung'!B8)/Annahmen!$B$59,0) -> 0 | D22: =IF(A22<=Annahmen!$B$59,('Kosten und Finanzierung'!B16-'Kosten und Finanzierung'!B8)*(Annahmen!$B$59-(A22-1))/Annahmen!$B$59,0) -> 0 | E22: =C22*$E$3 -> 0 | F22: =C22*$I$3 -> 0 | G22: =L21*Annahmen!$B$55/12 -> 2500 | H22: =M21*Annahmen!$B$56/12 -> 2868.75 | I22: =N21*Annahmen!$B$57/12 -> 7790.5553 | J22: =IF(AND(A22>=Annahmen!$B$62,A22<=Annahmen!$B$59),D22*Annahmen!$B$61/12,0) -> 0 | K22: =C22*$L$3+G22+H22+I22+J22 -> 13159.305 | L22: =L21+E22 -> 1200000 | M22: =M21+F22 -> 1147500 | N22: =N21+K22 -> 2350325.9
A23: 17 | B23: Anlaufzeit | C23: =IF(A23<=Annahmen!$B$59,('Kosten und Finanzierung'!B16-'Kosten und Finanzierung'!B8)/Annahmen!$B$59,0) -> 0 | D23: =IF(A23<=Annahmen!$B$59,('Kosten und Finanzierung'!B16-'Kosten und Finanzierung'!B8)*(Annahmen!$B$59-(A23-1))/Annahmen!$B$59,0) -> 0 | E23: =C23*$E$3 -> 0 | F23: =C23*$I$3 -> 0 | G23: =L22*Annahmen!$B$55/12 -> 2500 | H23: =M22*Annahmen!$B$56/12 -> 2868.75 | I23: =N22*Annahmen!$B$57/12 -> 7834.4196 | J23: =IF(AND(A23>=Annahmen!$B$62,A23<=Annahmen!$B$59),D23*Annahmen!$B$61/12,0) -> 0 | K23: =C23*$L$3+G23+H23+I23+J23 -> 13203.17 | L23: =L22+E23 -> 1200000 | M23: =M22+F23 -> 1147500 | N23: =N22+K23 -> 2363529.1
A24: 18 | B24: Anlaufzeit | C24: =IF(A24<=Annahmen!$B$59,('Kosten und Finanzierung'!B16-'Kosten und Finanzierung'!B8)/Annahmen!$B$59,0) -> 0 | D24: =IF(A24<=Annahmen!$B$59,('Kosten und Finanzierung'!B16-'Kosten und Finanzierung'!B8)*(Annahmen!$B$59-(A24-1))/Annahmen!$B$59,0) -> 0 | E24: =C24*$E$3 -> 0 | F24: =C24*$I$3 -> 0 | G24: =L23*Annahmen!$B$55/12 -> 2500 | H24: =M23*Annahmen!$B$56/12 -> 2868.75 | I24: =N23*Annahmen!$B$57/12 -> 7878.4302 | J24: =IF(AND(A24>=Annahmen!$B$62,A24<=Annahmen!$B$59),D24*Annahmen!$B$61/12,0) -> 0 | K24: =C24*$L$3+G24+H24+I24+J24 -> 13247.18 | L24: =L23+E24 -> 1200000 | M24: =M23+F24 -> 1147500 | N24: =N23+K24 -> 2376776.2
A25: 19 | B25: Anlaufzeit | C25: =IF(A25<=Annahmen!$B$59,('Kosten und Finanzierung'!B16-'Kosten und Finanzierung'!B8)/Annahmen!$B$59,0) -> 0 | D25: =IF(A25<=Annahmen!$B$59,('Kosten und Finanzierung'!B16-'Kosten und Finanzierung'!B8)*(Annahmen!$B$59-(A25-1))/Annahmen!$B$59,0) -> 0 | E25: =C25*$E$3 -> 0 | F25: =C25*$I$3 -> 0 | G25: =L24*Annahmen!$B$55/12 -> 2500 | H25: =M24*Annahmen!$B$56/12 -> 2868.75 | I25: =N24*Annahmen!$B$57/12 -> 7922.5875 | J25: =IF(AND(A25>=Annahmen!$B$62,A25<=Annahmen!$B$59),D25*Annahmen!$B$61/12,0) -> 0 | K25: =C25*$L$3+G25+H25+I25+J25 -> 13291.337 | L25: =L24+E25 -> 1200000 | M25: =M24+F25 -> 1147500 | N25: =N24+K25 -> 2390067.6
A26: 20 | B26: Anlaufzeit | C26: =IF(A26<=Annahmen!$B$59,('Kosten und Finanzierung'!B16-'Kosten und Finanzierung'!B8)/Annahmen!$B$59,0) -> 0 | D26: =IF(A26<=Annahmen!$B$59,('Kosten und Finanzierung'!B16-'Kosten und Finanzierung'!B8)*(Annahmen!$B$59-(A26-1))/Annahmen!$B$59,0) -> 0 | E26: =C26*$E$3 -> 0 | F26: =C26*$I$3 -> 0 | G26: =L25*Annahmen!$B$55/12 -> 2500 | H26: =M25*Annahmen!$B$56/12 -> 2868.75 | I26: =N25*Annahmen!$B$57/12 -> 7966.8919 | J26: =IF(AND(A26>=Annahmen!$B$62,A26<=Annahmen!$B$59),D26*Annahmen!$B$61/12,0) -> 0 | K26: =C26*$L$3+G26+H26+I26+J26 -> 13335.642 | L26: =L25+E26 -> 1200000 | M26: =M25+F26 -> 1147500 | N26: =N25+K26 -> 2403403.2
A27: 21 | B27: Anlaufzeit | C27: =IF(A27<=Annahmen!$B$59,('Kosten und Finanzierung'!B16-'Kosten und Finanzierung'!B8)/Annahmen!$B$59,0) -> 0 | D27: =IF(A27<=Annahmen!$B$59,('Kosten und Finanzierung'!B16-'Kosten und Finanzierung'!B8)*(Annahmen!$B$59-(A27-1))/Annahmen!$B$59,0) -> 0 | E27: =C27*$E$3 -> 0 | F27: =C27*$I$3 -> 0 | G27: =L26*Annahmen!$B$55/12 -> 2500 | H27: =M26*Annahmen!$B$56/12 -> 2868.75 | I27: =N26*Annahmen!$B$57/12 -> 8011.3441 | J27: =IF(AND(A27>=Annahmen!$B$62,A27<=Annahmen!$B$59),D27*Annahmen!$B$61/12,0) -> 0 | K27: =C27*$L$3+G27+H27+I27+J27 -> 13380.094 | L27: =L26+E27 -> 1200000 | M27: =M26+F27 -> 1147500 | N27: =N26+K27 -> 2416783.3
A28: 22 | B28: Anlaufzeit | C28: =IF(A28<=Annahmen!$B$59,('Kosten und Finanzierung'!B16-'Kosten und Finanzierung'!B8)/Annahmen!$B$59,0) -> 0 | D28: =IF(A28<=Annahmen!$B$59,('Kosten und Finanzierung'!B16-'Kosten und Finanzierung'!B8)*(Annahmen!$B$59-(A28-1))/Annahmen!$B$59,0) -> 0 | E28: =C28*$E$3 -> 0 | F28: =C28*$I$3 -> 0 | G28: =L27*Annahmen!$B$55/12 -> 2500 | H28: =M27*Annahmen!$B$56/12 -> 2868.75 | I28: =N27*Annahmen!$B$57/12 -> 8055.9444 | J28: =IF(AND(A28>=Annahmen!$B$62,A28<=Annahmen!$B$59),D28*Annahmen!$B$61/12,0) -> 0 | K28: =C28*$L$3+G28+H28+I28+J28 -> 13424.694 | L28: =L27+E28 -> 1200000 | M28: =M27+F28 -> 1147500 | N28: =N27+K28 -> 2430208
A29: 23 | B29: Anlaufzeit | C29: =IF(A29<=Annahmen!$B$59,('Kosten und Finanzierung'!B16-'Kosten und Finanzierung'!B8)/Annahmen!$B$59,0) -> 0 | D29: =IF(A29<=Annahmen!$B$59,('Kosten und Finanzierung'!B16-'Kosten und Finanzierung'!B8)*(Annahmen!$B$59-(A29-1))/Annahmen!$B$59,0) -> 0 | E29: =C29*$E$3 -> 0 | F29: =C29*$I$3 -> 0 | G29: =L28*Annahmen!$B$55/12 -> 2500 | H29: =M28*Annahmen!$B$56/12 -> 2868.75 | I29: =N28*Annahmen!$B$57/12 -> 8100.6934 | J29: =IF(AND(A29>=Annahmen!$B$62,A29<=Annahmen!$B$59),D29*Annahmen!$B$61/12,0) -> 0 | K29: =C29*$L$3+G29+H29+I29+J29 -> 13469.443 | L29: =L28+E29 -> 1200000 | M29: =M28+F29 -> 1147500 | N29: =N28+K29 -> 2443677.5
A30: 24 | B30: Anlaufzeit | C30: =IF(A30<=Annahmen!$B$59,('Kosten und Finanzierung'!B16-'Kosten und Finanzierung'!B8)/Annahmen!$B$59,0) -> 0 | D30: =IF(A30<=Annahmen!$B$59,('Kosten und Finanzierung'!B16-'Kosten und Finanzierung'!B8)*(Annahmen!$B$59-(A30-1))/Annahmen!$B$59,0) -> 0 | E30: =C30*$E$3 -> 0 | F30: =C30*$I$3 -> 0 | G30: =L29*Annahmen!$B$55/12 -> 2500 | H30: =M29*Annahmen!$B$56/12 -> 2868.75 | I30: =N29*Annahmen!$B$57/12 -> 8145.5915 | J30: =IF(AND(A30>=Annahmen!$B$62,A30<=Annahmen!$B$59),D30*Annahmen!$B$61/12,0) -> 0 | K30: =C30*$L$3+G30+H30+I30+J30 -> 13514.342 | L30: =L29+E30 -> 1200000 | M30: =M29+F30 -> 1147500 | N30: =N29+K30 -> 2457191.8
A31: 25 | B31: Anlaufzeit | C31: =IF(A31<=Annahmen!$B$59,('Kosten und Finanzierung'!B16-'Kosten und Finanzierung'!B8)/Annahmen!$B$59,0) -> 0 | D31: =IF(A31<=Annahmen!$B$59,('Kosten und Finanzierung'!B16-'Kosten und Finanzierung'!B8)*(Annahmen!$B$59-(A31-1))/Annahmen!$B$59,0) -> 0 | E31: =C31*$E$3 -> 0 | F31: =C31*$I$3 -> 0 | G31: =L30*Annahmen!$B$55/12 -> 2500 | H31: =M30*Annahmen!$B$56/12 -> 2868.75 | I31: =N30*Annahmen!$B$57/12 -> 8190.6393 | J31: =IF(AND(A31>=Annahmen!$B$62,A31<=Annahmen!$B$59),D31*Annahmen!$B$61/12,0) -> 0 | K31: =C31*$L$3+G31+H31+I31+J31 -> 13559.389 | L31: =L30+E31 -> 1200000 | M31: =M30+F31 -> 1147500 | N31: =N30+K31 -> 2470751.2
A32: 26 | B32: Anlaufzeit | C32: =IF(A32<=Annahmen!$B$59,('Kosten und Finanzierung'!B16-'Kosten und Finanzierung'!B8)/Annahmen!$B$59,0) -> 0 | D32: =IF(A32<=Annahmen!$B$59,('Kosten und Finanzierung'!B16-'Kosten und Finanzierung'!B8)*(Annahmen!$B$59-(A32-1))/Annahmen!$B$59,0) -> 0 | E32: =C32*$E$3 -> 0 | F32: =C32*$I$3 -> 0 | G32: =L31*Annahmen!$B$55/12 -> 2500 | H32: =M31*Annahmen!$B$56/12 -> 2868.75 | I32: =N31*Annahmen!$B$57/12 -> 8235.8373 | J32: =IF(AND(A32>=Annahmen!$B$62,A32<=Annahmen!$B$59),D32*Annahmen!$B$61/12,0) -> 0 | K32: =C32*$L$3+G32+H32+I32+J32 -> 13604.587 | L32: =L31+E32 -> 1200000 | M32: =M31+F32 -> 1147500 | N32: =N31+K32 -> 2484355.8
A33: 27 | B33: Rate-Start | C33: =IF(A33<=Annahmen!$B$59,('Kosten und Finanzierung'!B16-'Kosten und Finanzierung'!B8)/Annahmen!$B$59,0) -> 0 | D33: =IF(A33<=Annahmen!$B$59,('Kosten und Finanzierung'!B16-'Kosten und Finanzierung'!B8)*(Annahmen!$B$59-(A33-1))/Annahmen!$B$59,0) -> 0 | E33: =C33*$E$3 -> 0 | F33: =C33*$I$3 -> 0 | G33: =L32*Annahmen!$B$55/12 -> 2500 | H33: =M32*Annahmen!$B$56/12 -> 2868.75 | I33: =N32*Annahmen!$B$57/12 -> 8281.1859 | J33: =IF(AND(A33>=Annahmen!$B$62,A33<=Annahmen!$B$59),D33*Annahmen!$B$61/12,0) -> 0 | K33: =C33*$L$3+G33+H33+I33+J33 -> 13649.936 | L33: =L32+E33 -> 1200000 | M33: =M32+F33 -> 1147500 | N33: =N32+K33 -> 2498005.7
A34: Summe | B34: Summen | C34: =SUM(C6:C33) -> 4555831.5 | E34: =SUM(E6:E33) -> 1200000 | F34: =SUM(F6:F33) -> 1147500 | G34: =SUM(G6:G33) -> 48537.159 | H34: =SUM(H6:H33) -> 55696.39 | I34: =SUM(I6:I33) -> 153043.82 | J34: =SUM(J6:J33) -> 32396.816 | K34: =SUM(K6:K33) -> 2498005.7
A36: Finanzierungskosten gesamt (Zinsen und Bereitstellung): | G36: =SUM(G34:J34) -> 289674.18
A37: Kontrolle: Stand Rate-Start minus Ausgaben minus Finanzierungskosten (muss 0 sein) | G37: =ROUND(L33+M33+N33-C34-G36,2) -> 0

Sheet Tilgung Jahre
A1: Abzahlungsplan nach Jahren
A2: Zusammenfassung des monatlichen Tilgungsplans. Zinsbindung 10 Jahre, danach gleicher Zins angenommen.
A4: Jahr | B4: Zinsen | C4: Tilgung | D4: Kapitaldienst (Rate) | E4: Restschuld Jahresende | F4: davon KfW | G4: Zinsbindung
A5: 1 | B5: =SUMIFS(Tilgungsplan!$L$7:$L$426,Tilgungsplan!$B$7:$B$426,A5) -> 163584.57 | C5: =SUMIFS(Tilgungsplan!$M$7:$M$426,Tilgungsplan!$B$7:$B$426,A5) -> 49215.715 | D5: =B5+C5 -> 212800.29 | E5: =INDEX(Tilgungsplan!$O$7:$O$426,A5*12) -> 4796290 | F5: =INDEX(Tilgungsplan!$E$7:$E$426,A5*12)+INDEX(Tilgungsplan!$H$7:$H$426,A5*12) -> 2323727.4 | G5: bis Jahr 10
A6: 2 | B6: =SUMIFS(Tilgungsplan!$L$7:$L$426,Tilgungsplan!$B$7:$B$426,A6) -> 161887.15 | C6: =SUMIFS(Tilgungsplan!$M$7:$M$426,Tilgungsplan!$B$7:$B$426,A6) -> 50913.133 | D6: =B6+C6 -> 212800.29 | E6: =INDEX(Tilgungsplan!$O$7:$O$426,A6*12) -> 4745376.9 | F6: =INDEX(Tilgungsplan!$E$7:$E$426,A6*12)+INDEX(Tilgungsplan!$H$7:$H$426,A6*12) -> 2299294 | G6: bis Jahr 10
A7: 3 | B7: =SUMIFS(Tilgungsplan!$L$7:$L$426,Tilgungsplan!$B$7:$B$426,A7) -> 160128.98 | C7: =SUMIFS(Tilgungsplan!$M$7:$M$426,Tilgungsplan!$B$7:$B$426,A7) -> 52671.31 | D7: =B7+C7 -> 212800.29 | E7: =INDEX(Tilgungsplan!$O$7:$O$426,A7*12) -> 4692705.5 | F7: =INDEX(Tilgungsplan!$E$7:$E$426,A7*12)+INDEX(Tilgungsplan!$H$7:$H$426,A7*12) -> 2274181.3 | G7: bis Jahr 10
A8: 4 | B8: =SUMIFS(Tilgungsplan!$L$7:$L$426,Tilgungsplan!$B$7:$B$426,A8) -> 158307.8 | C8: =SUMIFS(Tilgungsplan!$M$7:$M$426,Tilgungsplan!$B$7:$B$426,A8) -> 54492.489 | D8: =B8+C8 -> 212800.29 | E8: =INDEX(Tilgungsplan!$O$7:$O$426,A8*12) -> 4638213.1 | F8: =INDEX(Tilgungsplan!$E$7:$E$426,A8*12)+INDEX(Tilgungsplan!$H$7:$H$426,A8*12) -> 2248370.2 | G8: bis Jahr 10
A9: 5 | B9: =SUMIFS(Tilgungsplan!$L$7:$L$426,Tilgungsplan!$B$7:$B$426,A9) -> 156421.29 | C9: =SUMIFS(Tilgungsplan!$M$7:$M$426,Tilgungsplan!$B$7:$B$426,A9) -> 56378.999 | D9: =B9+C9 -> 212800.29 | E9: =INDEX(Tilgungsplan!$O$7:$O$426,A9*12) -> 4581834.1 | F9: =INDEX(Tilgungsplan!$E$7:$E$426,A9*12)+INDEX(Tilgungsplan!$H$7:$H$426,A9*12) -> 2221841 | G9: bis Jahr 10
A10: 6 | B10: =SUMIFS(Tilgungsplan!$L$7:$L$426,Tilgungsplan!$B$7:$B$426,A10) -> 154467.03 | C10: =SUMIFS(Tilgungsplan!$M$7:$M$426,Tilgungsplan!$B$7:$B$426,A10) -> 58333.259 | D10: =B10+C10 -> 212800.29 | E10: =INDEX(Tilgungsplan!$O$7:$O$426,A10*12) -> 4523500.8 | F10: =INDEX(Tilgungsplan!$E$7:$E$426,A10*12)+INDEX(Tilgungsplan!$H$7:$H$426,A10*12) -> 2194573.8 | G10: bis Jahr 10
A11: 7 | B11: =SUMIFS(Tilgungsplan!$L$7:$L$426,Tilgungsplan!$B$7:$B$426,A11) -> 152442.51 | C11: =SUMIFS(Tilgungsplan!$M$7:$M$426,Tilgungsplan!$B$7:$B$426,A11) -> 60357.778 | D11: =B11+C11 -> 212800.29 | E11: =INDEX(Tilgungsplan!$O$7:$O$426,A11*12) -> 4463143 | F11: =INDEX(Tilgungsplan!$E$7:$E$426,A11*12)+INDEX(Tilgungsplan!$H$7:$H$426,A11*12) -> 2166547.7 | G11: bis Jahr 10
A12: 8 | B12: =SUMIFS(Tilgungsplan!$L$7:$L$426,Tilgungsplan!$B$7:$B$426,A12) -> 150345.13 | C12: =SUMIFS(Tilgungsplan!$M$7:$M$426,Tilgungsplan!$B$7:$B$426,A12) -> 62455.16 | D12: =B12+C12 -> 212800.29 | E12: =INDEX(Tilgungsplan!$O$7:$O$426,A12*12) -> 4400687.9 | F12: =INDEX(Tilgungsplan!$E$7:$E$426,A12*12)+INDEX(Tilgungsplan!$H$7:$H$426,A12*12) -> 2137741.4 | G12: bis Jahr 10
A13: 9 | B13: =SUMIFS(Tilgungsplan!$L$7:$L$426,Tilgungsplan!$B$7:$B$426,A13) -> 148172.18 | C13: =SUMIFS(Tilgungsplan!$M$7:$M$426,Tilgungsplan!$B$7:$B$426,A13) -> 64628.109 | D13: =B13+C13 -> 212800.29 | E13: =INDEX(Tilgungsplan!$O$7:$O$426,A13*12) -> 4336059.8 | F13: =INDEX(Tilgungsplan!$E$7:$E$426,A13*12)+INDEX(Tilgungsplan!$H$7:$H$426,A13*12) -> 2108133.2 | G13: bis Jahr 10
A14: 10 | B14: =SUMIFS(Tilgungsplan!$L$7:$L$426,Tilgungsplan!$B$7:$B$426,A14) -> 145920.85 | C14: =SUMIFS(Tilgungsplan!$M$7:$M$426,Tilgungsplan!$B$7:$B$426,A14) -> 66879.43 | D14: =B14+C14 -> 212800.29 | E14: =INDEX(Tilgungsplan!$O$7:$O$426,A14*12) -> 4269180.3 | F14: =INDEX(Tilgungsplan!$E$7:$E$426,A14*12)+INDEX(Tilgungsplan!$H$7:$H$426,A14*12) -> 2077700.3 | G14: bis Jahr 10
A15: 11 | B15: =SUMIFS(Tilgungsplan!$L$7:$L$426,Tilgungsplan!$B$7:$B$426,A15) -> 143588.25 | C15: =SUMIFS(Tilgungsplan!$M$7:$M$426,Tilgungsplan!$B$7:$B$426,A15) -> 69212.039 | D15: =B15+C15 -> 212800.29 | E15: =INDEX(Tilgungsplan!$O$7:$O$426,A15*12) -> 4199968.3 | F15: =INDEX(Tilgungsplan!$E$7:$E$426,A15*12)+INDEX(Tilgungsplan!$H$7:$H$426,A15*12) -> 2046419.8 | G15: Anschluss
A16: 12 | B16: =SUMIFS(Tilgungsplan!$L$7:$L$426,Tilgungsplan!$B$7:$B$426,A16) -> 141171.33 | C16: =SUMIFS(Tilgungsplan!$M$7:$M$426,Tilgungsplan!$B$7:$B$426,A16) -> 71628.957 | D16: =B16+C16 -> 212800.29 | E16: =INDEX(Tilgungsplan!$O$7:$O$426,A16*12) -> 4128339.3 | F16: =INDEX(Tilgungsplan!$E$7:$E$426,A16*12)+INDEX(Tilgungsplan!$H$7:$H$426,A16*12) -> 2014267.7 | G16: Anschluss
... A39: 35 | B39: =SUMIFS(Tilgungsplan!$L$7:$L$426,Tilgungsplan!$B$7:$B$426,A39) -> 53295.593 | C39: =SUMIFS(Tilgungsplan!$M$7:$M$426,Tilgungsplan!$B$7:$B$426,A39) -> 159504.69 | D39: =B39+C39 -> 212800.29 | E39: =INDEX(Tilgungsplan!$O$7:$O$426,A39*12) -> 1563885.3 | F39: =INDEX(Tilgungsplan!$E$7:$E$426,A39*12)+INDEX(Tilgungsplan!$H$7:$H$426,A39*12) -> 967967.19 | G39: Anschluss
A41: Summe | B41: =SUM(B5:B39) -> 4166389.6 | C41: =SUM(C5:C39) -> 3281620.4 | D41: =SUM(D5:D39) -> 7448010

Sheet Tilgungsplan
A1: Abzahlungsplan (Tilgungsplan) monatlich, 35 Jahre
A2: Annuitätendarlehen: Rate = Darlehen × (Zins + Anfangstilgung) / 12. Nach 10 Jahren Zinsbindung wird der gleiche Zins angenommen. | C2: KfW Wohnen | F2: KfW Gastro | I2: Hausbank | N2: Summe
A3: Rate pro Monat | C3: =E6*(Annahmen!$B$55+Annahmen!$B$58)/12 -> 3500 | F3: =H6*(Annahmen!$B$56+Annahmen!$B$58)/12 -> 3825 | I3: =K6*(Annahmen!$B$57+Annahmen!$B$58)/12 -> 10408.357 | N3: =C3+F3+I3 -> 17733.357
A5: Monat | B5: Jahr | C5: Zins KfW Wohnen | D5: Tilgung KfW Wohnen | E5: Rest KfW Wohnen | F5: Zins KfW Gastro | G5: Tilgung KfW Gastro | H5: Rest KfW Gastro | I5: Zins Hausbank | J5: Tilgung Hausbank | K5: Rest Hausbank | L5: Zinsen gesamt | M5: Tilgung gesamt | N5: Rate gesamt | O5: Restschuld gesamt
A6: 0 | B6: 0 | E6: =Bauphase!L33 -> 1200000 | H6: =Bauphase!M33 -> 1147500 | K6: =Bauphase!N33 -> 2498005.7 | O6: =E6+H6+K6 -> 4845505.7
A7: 1 | B7: =ROUNDUP(A7/12,0) -> 1 | C7: =E6*Annahmen!$B$55/12 -> 2500 | D7: =MIN($C$3-C7,E6) -> 1000 | E7: =E6-D7 -> 1199000 | F7: =H6*Annahmen!$B$56/12 -> 2868.75 | G7: =MIN($F$3-F7,H6) -> 956.25 | H7: =H6-G7 -> 1146543.8 | I7: =K6*Annahmen!$B$57/12 -> 8326.6857 | J7: =MIN($I$3-I7,K6) -> 2081.6714 | K7: =K6-J7 -> 2495924 | L7: =C7+F7+I7 -> 13695.436 | M7: =D7+G7+J7 -> 4037.9214 | N7: =L7+M7 -> 17733.357 | O7: =E7+H7+K7 -> 4841467.8
A8: 2 | B8: =ROUNDUP(A8/12,0) -> 1 | C8: =E7*Annahmen!$B$55/12 -> 2497.9167 | D8: =MIN($C$3-C8,E7) -> 1002.0833 | E8: =E7-D8 -> 1197997.9 | F8: =H7*Annahmen!$B$56/12 -> 2866.3594 | G8: =MIN($F$3-F8,H7) -> 958.64062 | H8: =H7-G8 -> 1145585.1 | I8: =K7*Annahmen!$B$57/12 -> 8319.7468 | J8: =MIN($I$3-I8,K7) -> 2088.6103 | K8: =K7-J8 -> 2493835.4 | L8: =C8+F8+I8 -> 13684.023 | M8: =D8+G8+J8 -> 4049.3343 | N8: =L8+M8 -> 17733.357 | O8: =E8+H8+K8 -> 4837418.5
A9: 3 | B9: =ROUNDUP(A9/12,0) -> 1 | C9: =E8*Annahmen!$B$55/12 -> 2495.829 | D9: =MIN($C$3-C9,E8) -> 1004.171 | E9: =E8-D9 -> 1196993.7 | F9: =H8*Annahmen!$B$56/12 -> 2863.9628 | G9: =MIN($F$3-F9,H8) -> 961.03723 | H9: =H8-G9 -> 1144624.1 | I9: =K8*Annahmen!$B$57/12 -> 8312.7847 | J9: =MIN($I$3-I9,K8) -> 2095.5724 | K9: =K8-J9 -> 2491739.9 | L9: =C9+F9+I9 -> 13672.577 | M9: =D9+G9+J9 -> 4060.7806 | N9: =L9+M9 -> 17733.357 | O9: =E9+H9+K9 -> 4833357.7
A10: 4 | B10: =ROUNDUP(A10/12,0) -> 1 | C10: =E9*Annahmen!$B$55/12 -> 2493.737 | D10: =MIN($C$3-C10,E9) -> 1006.263 | E10: =E9-D10 -> 1195987.5 | F10: =H9*Annahmen!$B$56/12 -> 2861.5602 | G10: =MIN($F$3-F10,H9) -> 963.43982 | H10: =H9-G10 -> 1143660.6 | I10: =K9*Annahmen!$B$57/12 -> 8305.7995 | J10: =MIN($I$3-I10,K9) -> 2102.5576 | K10: =K9-J10 -> 2489637.3 | L10: =C10+F10+I10 -> 13661.097 | M10: =D10+G10+J10 -> 4072.2605 | N10: =L10+M10 -> 17733.357 | O10: =E10+H10+K10 -> 4829285.4
A11: 5 | B11: =ROUNDUP(A11/12,0) -> 1 | C11: =E10*Annahmen!$B$55/12 -> 2491.6406 | D11: =MIN($C$3-C11,E10) -> 1008.3594 | E11: =E10-D11 -> 1194979.1 | F11: =H10*Annahmen!$B$56/12 -> 2859.1516 | G11: =MIN($F$3-F11,H10) -> 965.84842 | H11: =H10-G11 -> 1142694.8 | I11: =K10*Annahmen!$B$57/12 -> 8298.791 | J11: =MIN($I$3-I11,K10) -> 2109.5661 | K11: =K10-J11 -> 2487527.7 | L11: =C11+F11+I11 -> 13649.583 | M11: =D11+G11+J11 -> 4083.774 | N11: =L11+M11 -> 17733.357 | O11: =E11+H11+K11 -> 4825201.6
A12: 6 | B12: =ROUNDUP(A12/12,0) -> 1 | C12: =E11*Annahmen!$B$55/12 -> 2489.5398 | D12: =MIN($C$3-C12,E11) -> 1010.4602 | E12: =E11-D12 -> 1193968.7 | F12: =H11*Annahmen!$B$56/12 -> 2856.737 | G12: =MIN($F$3-F12,H11) -> 968.26304 | H12: =H11-G12 -> 1141726.5 | I12: =K11*Annahmen!$B$57/12 -> 8291.7591 | J12: =MIN($I$3-I12,K11) -> 2116.598 | K12: =K11-J12 -> 2485411.1 | L12: =C12+F12+I12 -> 13638.036 | M12: =D12+G12+J12 -> 4095.3212 | N12: =L12+M12 -> 17733.357 | O12: =E12+H12+K12 -> 4821106.3
A13: 7 | B13: =ROUNDUP(A13/12,0) -> 1 | C13: =E12*Annahmen!$B$55/12 -> 2487.4347 | D13: =MIN($C$3-C13,E12) -> 1012.5653 | E13: =E12-D13 -> 1192956.1 | F13: =H12*Annahmen!$B$56/12 -> 2854.3163 | G13: =MIN($F$3-F13,H12) -> 970.6837 | H13: =H12-G13 -> 1140755.8 | I13: =K12*Annahmen!$B$57/12 -> 8284.7038 | J13: =MIN($I$3-I13,K12) -> 2123.6533 | K13: =K12-J13 -> 2483287.5 | L13: =C13+F13+I13 -> 13626.455 | M13: =D13+G13+J13 -> 4106.9023 | N13: =L13+M13 -> 17733.357 | O13: =E13+H13+K13 -> 4816999.4
A14: 8 | B14: =ROUNDUP(A14/12,0) -> 1 | C14: =E13*Annahmen!$B$55/12 -> 2485.3252 | D14: =MIN($C$3-C14,E13) -> 1014.6748 | E14: =E13-D14 -> 1191941.4 | F14: =H13*Annahmen!$B$56/12 -> 2851.8896 | G14: =MIN($F$3-F14,H13) -> 973.11041 | H14: =H13-G14 -> 1139782.7 | I14: =K13*Annahmen!$B$57/12 -> 8277.6249 | J14: =MIN($I$3-I14,K13) -> 2130.7322 | K14: =K13-J14 -> 2481156.7 | L14: =C14+F14+I14 -> 13614.84 | M14: =D14+G14+J14 -> 4118.5174 | N14: =L14+M14 -> 17733.357 | O14: =E14+H14+K14 -> 4812880.9
A15: 9 | B15: =ROUNDUP(A15/12,0) -> 1 | C15: =E14*Annahmen!$B$55/12 -> 2483.2113 | D15: =MIN($C$3-C15,E14) -> 1016.7887 | E15: =E14-D15 -> 1190924.6 | F15: =H14*Annahmen!$B$56/12 -> 2849.4568 | G15: =MIN($F$3-F15,H14) -> 975.54318 | H15: =H14-G15 -> 1138807.2 | I15: =K14*Annahmen!$B$57/12 -> 8270.5225 | J15: =MIN($I$3-I15,K14) -> 2137.8346 | K15: =K14-J15 -> 2479018.9 | L15: =C15+F15+I15 -> 13603.191 | M15: =D15+G15+J15 -> 4130.1665 | N15: =L15+M15 -> 17733.357 | O15: =E15+H15+K15 -> 4808750.7
A16: 10 | B16: =ROUNDUP(A16/12,0) -> 1 | C16: =E15*Annahmen!$B$55/12 -> 2481.093 | D16: =MIN($C$3-C16,E15) -> 1018.907 | E16: =E15-D16 -> 1189905.7 | F16: =H15*Annahmen!$B$56/12 -> 2847.018 | G16: =MIN($F$3-F16,H15) -> 977.98204 | H16: =H15-G16 -> 1137829.2 | I16: =K15*Annahmen!$B$57/12 -> 8263.3964 | J16: =MIN($I$3-I16,K15) -> 2144.9607 | K16: =K15-J16 -> 2476873.9 | L16: =C16+F16+I16 -> 13591.507 | M16: =D16+G16+J16 -> 4141.8498 | N16: =L16+M16 -> 17733.357 | O16: =E16+H16+K16 -> 4804608.9
A17: 11 | B17: =ROUNDUP(A17/12,0) -> 1 | C17: =E16*Annahmen!$B$55/12 -> 2478.9703 | D17: =MIN($C$3-C17,E16) -> 1021.0297 | E17: =E16-D17 -> 1188884.7 | F17: =H16*Annahmen!$B$56/12 -> 2844.573 | G17: =MIN($F$3-F17,H16) -> 980.427 | H17: =H16-G17 -> 1136848.8 | I17: =K16*Annahmen!$B$57/12 -> 8256.2465 | J17: =MIN($I$3-I17,K16) -> 2152.1106 | K17: =K16-J17 -> 2474721.8 | L17: =C17+F17+I17 -> 13579.79 | M17: =D17+G17+J17 -> 4153.5673 | N17: =L17+M17 -> 17733.357 | O17: =E17+H17+K17 -> 4800455.3
A18: 12 | B18: =ROUNDUP(A18/12,0) -> 1 | C18: =E17*Annahmen!$B$55/12 -> 2476.8431 | D18: =MIN($C$3-C18,E17) -> 1023.1569 | E18: =E17-D18 -> 1187861.5 | F18: =H17*Annahmen!$B$56/12 -> 2842.1219 | G18: =MIN($F$3-F18,H17) -> 982.87806 | H18: =H17-G18 -> 1135865.9 | I18: =K17*Annahmen!$B$57/12 -> 8249.0728 | J18: =MIN($I$3-I18,K17) -> 2159.2843 | K18: =K17-J18 -> 2472562.6 | L18: =C18+F18+I18 -> 13568.038 | M18: =D18+G18+J18 -> 4165.3193 | N18: =L18+M18 -> 17733.357 | O18: =E18+H18+K18 -> 4796290
... A426: 420 | B426: =ROUNDUP(A426/12,0) -> 35 | C426: =E425*Annahmen!$B$55/12 -> 1108.2899 | D426: =MIN($C$3-C426,E425) -> 2391.7101 | E426: =E425-D426 -> 529587.43 | F426: =H425*Annahmen!$B$56/12 -> 1102.755 | G426: =MIN($F$3-F426,H425) -> 2722.245 | H426: =H425-G426 -> 438379.75 | I426: =K425*Annahmen!$B$57/12 -> 2014.3737 | J426: =MIN($I$3-I426,K425) -> 8393.9834 | K426: =K425-J426 -> 595918.13 | L426: =C426+F426+I426 -> 4225.4186 | M426: =D426+G426+J426 -> 13507.939 | N426: =L426+M426 -> 17733.357 | O426: =E426+H426+K426 -> 1563885.3

Sheet Ertrag und Cashflow
A1: Ertrag und Kapitaldienst (erstes Jahr nach der Anlaufzeit)
A2: Für die Bank: reicht der Ertrag für Zinsen und Tilgung? Kapitaldienstdeckung (DSCR) = Ertrag vor Kapitaldienst / Kapitaldienst.
A4: Position | B4: pro Monat | C4: pro Jahr | D4: Hinweis
A5: Kaltmiete Wohnen (vermietete Wohnungen) | B5: ='Flächen und Mieten'!F21 -> 7320.5882 | C5: =B5*12 -> 87847.059
A6: Büromieten (2 Ankermieter) | B6: ='Flächen und Mieten'!F25 -> 1600 | C6: =B6*12 -> 19200 | D6: 10 Jahre fest, Indexmiete
A7: Pacht Gastro | B7: ='Flächen und Mieten'!F22 -> 5100 | C7: =B7*12 -> 61200 | D7: Gastro zahlt an das Haus
A8: Rücklagen (Verwaltung, Instandhaltung, Leerstand) | B8: =-Annahmen!$B$48*(B5+B6+B7) -> -1402.0588 | C8: =B8*12 -> -16824.706 | D8: 10 % von Miete, Büro und Pacht
A9: Nettoertrag Immobilie | B9: =SUM(B5:B8) -> 12618.529 | C9: =B9*12 -> 151422.35
A10: Betriebsergebnis Gastro nach Pacht | B10: ='Gastro Betrieb'!C19 -> 14728.05 | C10: =B10*12 -> 176736.6 | D10: Betreiber = Bauherr, ohne Lohn
A11: Nettoertrag vor Kapitaldienst | B11: =B9+B10 -> 27346.579 | C11: =B11*12 -> 328158.95
A12: Kapitaldienst (Zinsen und Tilgung aller Darlehen) | B12: =-Tilgungsplan!N3 -> -17733.357 | C12: =B12*12 -> -212800.29
A13: Ergebnis pro Monat nach Kapitaldienst | B13: =B11+B12 -> 9613.2223 | C13: =B13*12 -> 115358.67 | D13: ohne Lohn des Bauherrn
A15: Kapitaldienstdeckung gesamt (DSCR) | B15: =B11/-B12 -> 1.5420983 | D15: Bank verlangt meist mindestens 1,2
A16: Kapitaldienstdeckung nur Immobilie (Wohnen, Büro, Pacht) | B16: =B9/-B12 -> 0.71157025 | D16: ohne Gastro-Gewinn
A17: Kapitaldienstdeckung nur langfristige Mieten (Wohnen, Büro) | B17: =(B5+B6)*(1-Annahmen!$B$48)/-B12 -> 0.45273601 | D17: ohne Pacht und Gastro: Ankermieter helfen hier
A18: Zinsdeckung (Ertrag vor Kapitaldienst / Zinsen) | B18: =B11/('Tilgung Jahre'!B5/12) -> 2.0060508
A19: Anfangsrendite auf Gesamtkosten (Nettoertrag Immobilie p. a.) | B19: =C9/'Kosten und Finanzierung'!B18 -> 0.031250062
A20: Break-even Gastro-Umsatz (Haus insgesamt Ergebnis = 0) | B20: =(-B9-B12+'Flächen und Mieten'!F22+Annahmen!$B$51)/Annahmen!$B$50 -> 33491.238 | D20: Umsatz, ab dem Zinsen und Tilgung aller Darlehen bezahlt sind
A21: Anteil der Büro-Ankermieter am Rohertrag | B21: ='Flächen und Mieten'!G25/'Flächen und Mieten'!G26 -> 0.11411789

Sheet Gastro Betrieb
A1: Gastro-Betrieb: Umsatz, Kosten, Ergebnis pro Monat
A2: Richtwerte aus der Branche, keine Werte aus Werlte. Lohn des Bauherrn ist nicht gerechnet.
A4: Posten | B4: Anteil | C4: Betrag / Monat | D4: Hinweis
A5: Umsatz (netto) | C5: =Annahmen!$B$49 -> 65010
A6: Wareneinsatz (Einkauf Essen und Getränke) | B6: 0.28 | C6: =-$C$5*B6 -> -18202.8
A7: Personal (ohne Lohn des Bauherrn) | B7: 0.3 | C7: =-$C$5*B7 -> -19503
A8: Energie, Wasser, Müll | B8: 0.03 | C8: =-$C$5*B8 -> -1950.3
A9: Reinigung, Wäsche, Verbrauchsmaterial | B9: 0.02 | C9: =-$C$5*B9 -> -1300.2
A10: Werbung und Marketing | B10: 0.015 | C10: =-$C$5*B10 -> -975.15
A11: Reparaturen, Wartung, Kassensystem | B11: 0.015 | C11: =-$C$5*B11 -> -975.15
A12: Sonstiges | B12: 0.015 | C12: =-$C$5*B12 -> -975.15
A13: Versicherungen, GEMA, Gebühren | B13: 0.01 | C13: =-$C$5*B13 -> -650.1
A14: Steuerberater, Buchhaltung | B14: 0.01 | C14: =-$C$5*B14 -> -650.1
A15: Summe Betriebskosten ohne Pacht | B15: =SUM(B6:B14) -> 0.695 | C15: =SUM(C6:C14) -> -45181.95
A16: Gewinn vor Pacht | B16: =1-B15 -> 0.305 | C16: =C5+C15 -> 19828.05 | D16: Marge laut Annahmen muss mit 30,5 % übereinstimmen
A17: Pacht an das Haus | C17: =-'Flächen und Mieten'!F22 -> -5100
A18: Lohn des Bauherrn | C18: =-Annahmen!$B$51 -> 0
A19: Betriebsergebnis nach Pacht | C19: =C16+C17+C18 -> 14728.05
A20: Break-even-Umsatz des Betriebs (Ergebnis nach Pacht = 0) | C20: =('Flächen und Mieten'!F22+Annahmen!$B$51)/B16 -> 16721.311
A23: Umsatz pro Monat | C23: Gewinn vor Pacht | D23: Gewinn nach Pacht
A24: 40000 | C24: =A24*$B$16 -> 12200 | D24: =C24-'Flächen und Mieten'!$F$22-Annahmen!$B$51 -> 7100
A25: 50000 | C25: =A25*$B$16 -> 15250 | D25: =C25-'Flächen und Mieten'!$F$22-Annahmen!$B$51 -> 10150
A26: =Annahmen!$B$49 -> 65010 | C26: =A26*$B$16 -> 19828.05 | D26: =C26-'Flächen und Mieten'!$F$22-Annahmen!$B$51 -> 14728.05
A27: 80000 | C27: =A27*$B$16 -> 24400 | D27: =C27-'Flächen und Mieten'!$F$22-Annahmen!$B$51 -> 19300
A28: 95000 | C28: =A28*$B$16 -> 28975 | D28: =C28-'Flächen und Mieten'!$F$22-Annahmen!$B$51 -> 23875
A30: Bei sehr niedrigem Umsatz drücken Fixkosten stärker: die Rechnung ist dort zu günstig.

Sheet Gastro Tagesteile
A1: Gastro-Umsatz nach Tagesteilen: Frühstück, Mittag, Bar am Abend
A2: Tagsüber Frühstück und Bowls, abends Bar mit Snacks. Öffnungstage, Gäste und Bon sind Annahmen (keine Marktdaten für Werlte), Ruhetag Montag.
A4: Tagesteil | B4: Zeit | C4: Tage / Monat | D4: Gäste / Tag | E4: Ø Bon (€) | F4: Umsatz / Monat | G4: Anteil
A5: Frühstück werktags | B5: Di–Fr 08:00–11:00 | C5: 17 | D5: 30 | E5: 11 | F5: =C5*D5*E5 -> 5610 | G5: =F5/$F$14 -> 0.086294416
A6: Brunch am Wochenende | B6: Sa, So 09:00–14:00 | C6: 9 | D6: 60 | E6: 14 | F6: =C6*D6*E6 -> 7560 | G6: =F6/$F$14 -> 0.1162898
A7: Mittag: Bowls, Salate, Suppe | B7: Di–Fr 11:30–14:30 | C7: 17 | D7: 40 | E7: 13 | F7: =C7*D7*E7 -> 8840 | G7: =F7/$F$14 -> 0.13597908
A8: Nachmittag: Kaffee, Kuchen, Snacks | B8: Di–So 14:30–17:00 | C8: 26 | D8: 20 | E8: 7 | F8: =C8*D8*E8 -> 3640 | G8: =F8/$F$14 -> 0.055991386
A9: Bar mit Snacks Di–Do, So | B9: ab 17:00 | C9: 17 | D9: 35 | E9: 20 | F9: =C9*D9*E9 -> 11900 | G9: =F9/$F$14 -> 0.18304876
A10: Bar Fr, Sa (bis 01:00) | B10: Cocktails, Wein, Bier, Snacks | C10: 9 | D10: 90 | E10: 26 | F10: =C10*D10*E10 -> 21060 | G10: =F10/$F$14 -> 0.32395016
A11: Events: Live-Musik, Feiern | B11: nach Absprache, 4 pro Monat | C11: 4 | D11: 40 | E11: 40 | F11: =C11*D11*E11 -> 6400 | G11: =F11/$F$14 -> 0.098446393
A14: Gastro-Umsatz pro Monat (netto) | F14: =SUM(F5:F11) -> 65010 | G14: =SUM(G5:G11) -> 1
A15: davon Tag (Frühstück, Brunch, Mittag, Nachmittag) | F15: =SUM(F5:F8) -> 25650 | G15: =F15/F14 -> 0.39455468
A16: davon Abend (Bar mit Snacks, Events) | F16: =SUM(F9:F11) -> 39360 | G16: =F16/F14 -> 0.60544532
A17: Gäste pro Monat | F17: =SUMPRODUCT(C5:C11,D5:D11) -> 3815
A18: Umsatz je Platz und Jahr (190 Plätze) | F18: =F14*12/(Annahmen!$B$36+Annahmen!$B$37) -> 4105.8947
A19: Auslastung der Plätze an der Bar Fr, Sa (Gäste je Abend / Plätze) | F19: =D10/(Annahmen!$B$36+Annahmen!$B$37) -> 0.47368421
A21: Einordnung: Die Bar mit Snacks am Abend trägt den größten Teil des Umsatzes, Frühstück und Bowls füllen das Haus am Tag. Terrasse im Sommer, Catering und Weihnachtsfeiern sind nicht eingerechnet. Branchen-Median Österreich ca. 12.000 € je Platz und Jahr.

Sheet Ertragswert
A1: Ertragswert und Beleihung
A2: Ertragswertverfahren nach ImmoWertV (vereinfacht) getrennt nach Wohnen, Büro und Gastro. Ein Gutachter der Bank ermittelt den verbindlichen Beleihungswert.
A4: Ertragswert nach Nutzung | B4: Wohnen | C4: Büro | D4: Gastro | E4: Summe | F4: Hinweis
A5: Rohertrag pro Jahr | B5: ='Flächen und Mieten'!G20 -> 87847.059 | C5: ='Flächen und Mieten'!G25 -> 19200 | D5: ='Flächen und Mieten'!G22 -> 61200 | E5: =SUM(B5:D5) -> 168247.06
A6: Verwaltungskosten | B6: =-(Annahmen!$B$24+Annahmen!$B$26)*Annahmen!$B$69 -> -2880 | C6: =-C5*Annahmen!$B$72 -> -576 | D6: =-D5*Annahmen!$B$72 -> -1836
A7: Instandhaltung | B7: =-(Annahmen!$B$23+Annahmen!$B$25)*Annahmen!$B$70 -> -7860 | C7: =-(Annahmen!$B$29+Annahmen!$B$31)*Annahmen!$B$73 -> -1320 | D7: =-Annahmen!$B$21*Annahmen!$B$73 -> -4080
A8: Mietausfallwagnis | B8: =-B5*Annahmen!$B$71 -> -1756.9412 | C8: =-C5*Annahmen!$B$75 -> -384 | D8: =-D5*Annahmen!$B$74 -> -2448
A9: Bewirtschaftungskosten | B9: =SUM(B6:B8) -> -12496.941 | C9: =SUM(C6:C8) -> -2280 | D9: =SUM(D6:D8) -> -8364 | E9: =SUM(B9:D9) -> -23140.941
A10: Reinertrag | B10: =B5+B9 -> 75350.118 | C10: =C5+C9 -> 16920 | D10: =D5+D9 -> 52836 | E10: =SUM(B10:D10) -> 145106.12
A11: Flächenanteil (für die Verteilung des Bodenwerts) | B11: =(Annahmen!$B$23+Annahmen!$B$25)/((Annahmen!$B$23+Annahmen!$B$25)+Annahmen!$B$29+Annahmen!$B$31+Annahmen!$B$21) -> 0.4924812 | C11: =(Annahmen!$B$29+Annahmen!$B$31)/((Annahmen!$B$23+Annahmen!$B$25)+Annahmen!$B$29+Annahmen!$B$31+Annahmen!$B$21) -> 0.12406015 | D11: =1-B11-C11 -> 0.38345865 | E11: =SUM(B11:D11) -> 1
A12: Bodenwertanteil (Bodenwert 960 m² × 230 €) | B12: =$E$12*B11 -> 108739.85 | C12: =$E$12*C11 -> 27392.481 | D12: =$E$12*D11 -> 84667.669 | E12: =Annahmen!$B$5*Annahmen!$B$6 -> 220800
A13: Liegenschaftszins | B13: =Annahmen!$B$64 -> 0.04 | C13: =Annahmen!$B$65 -> 0.06 | D13: =Annahmen!$B$66 -> 0.065
